[2025-03-27T04:43:31.548+0530] {local_task_job_runner.py:123} INFO - ::group::Pre task execution logs
[2025-03-27T04:43:31.553+0530] {taskinstance.py:2614} INFO - Dependencies all met for dep_context=non-requeueable deps ti=<TaskInstance: stock_etl_pipeline.run_etl scheduled__2025-03-26T20:40:00+00:00 [queued]>
[2025-03-27T04:43:31.556+0530] {taskinstance.py:2614} INFO - Dependencies all met for dep_context=requeueable deps ti=<TaskInstance: stock_etl_pipeline.run_etl scheduled__2025-03-26T20:40:00+00:00 [queued]>
[2025-03-27T04:43:31.556+0530] {taskinstance.py:2867} INFO - Starting attempt 2 of 2
[2025-03-27T04:43:31.563+0530] {taskinstance.py:2890} INFO - Executing <Task(PythonOperator): run_etl> on 2025-03-26 20:40:00+00:00
[2025-03-27T04:43:31.566+0530] {standard_task_runner.py:72} INFO - Started process 12745 to run task
[2025-03-27T04:43:31.571+0530] {standard_task_runner.py:104} INFO - Running: ['airflow', 'tasks', 'run', 'stock_etl_pipeline', 'run_etl', 'scheduled__2025-03-26T20:40:00+00:00', '--job-id', '126', '--raw', '--subdir', 'DAGS_FOLDER/stock_etl_dag.py', '--cfg-path', '/var/folders/85/tszsn_6n56zfd9b9p9l13r9c0000gn/T/tmpb6bq01qa']
[2025-03-27T04:43:31.572+0530] {standard_task_runner.py:105} INFO - Job 126: Subtask run_etl
[2025-03-27T04:43:31.589+0530] {task_command.py:467} INFO - Running <TaskInstance: stock_etl_pipeline.run_etl scheduled__2025-03-26T20:40:00+00:00 [running]> on host Utkarshs-MacBook-Air.local
[2025-03-27T04:43:31.611+0530] {taskinstance.py:3134} INFO - Exporting env vars: AIRFLOW_CTX_DAG_OWNER='airflow' AIRFLOW_CTX_DAG_ID='stock_etl_pipeline' AIRFLOW_CTX_TASK_ID='run_etl' AIRFLOW_CTX_EXECUTION_DATE='2025-03-26T20:40:00+00:00' AIRFLOW_CTX_TRY_NUMBER='2' AIRFLOW_CTX_DAG_RUN_ID='scheduled__2025-03-26T20:40:00+00:00'
[2025-03-27T04:43:31.611+0530] {logging_mixin.py:190} INFO - Task instance is in running state
[2025-03-27T04:43:31.611+0530] {logging_mixin.py:190} INFO -  Previous state of the Task instance: queued
[2025-03-27T04:43:31.612+0530] {logging_mixin.py:190} INFO - Current task name:run_etl state:running start_date:2025-03-26 23:13:31.553939+00:00
[2025-03-27T04:43:31.612+0530] {logging_mixin.py:190} INFO - Dag name:stock_etl_pipeline and current dag run status:running
[2025-03-27T04:43:31.612+0530] {taskinstance.py:732} INFO - ::endgroup::
[2025-03-27T04:43:31.615+0530] {taskinstance.py:3313} ERROR - Task failed with exception
Traceback (most recent call last):
  File "/Users/uk/miniforge3/lib/python3.10/site-packages/urllib3/connection.py", line 174, in _new_conn
    conn = connection.create_connection(
  File "/Users/uk/miniforge3/lib/python3.10/site-packages/urllib3/util/connection.py", line 72, in create_connection
    for res in socket.getaddrinfo(host, port, family, socket.SOCK_STREAM):
  File "/Users/uk/miniforge3/lib/python3.10/socket.py", line 955, in getaddrinfo
    for res in _socket.getaddrinfo(host, port, family, type, proto, flags):
socket.gaierror: [Errno 8] nodename nor servname provided, or not known

During handling of the above exception, another exception occurred:

Traceback (most recent call last):
  File "/Users/uk/miniforge3/lib/python3.10/site-packages/urllib3/connectionpool.py", line 714, in urlopen
    httplib_response = self._make_request(
  File "/Users/uk/miniforge3/lib/python3.10/site-packages/urllib3/connectionpool.py", line 403, in _make_request
    self._validate_conn(conn)
  File "/Users/uk/miniforge3/lib/python3.10/site-packages/urllib3/connectionpool.py", line 1053, in _validate_conn
    conn.connect()
  File "/Users/uk/miniforge3/lib/python3.10/site-packages/urllib3/connection.py", line 363, in connect
    self.sock = conn = self._new_conn()
  File "/Users/uk/miniforge3/lib/python3.10/site-packages/urllib3/connection.py", line 186, in _new_conn
    raise NewConnectionError(
urllib3.exceptions.NewConnectionError: <urllib3.connection.HTTPSConnection object at 0x144a0ffd0>: Failed to establish a new connection: [Errno 8] nodename nor servname provided, or not known

During handling of the above exception, another exception occurred:

Traceback (most recent call last):
  File "/Users/uk/miniforge3/lib/python3.10/site-packages/requests/adapters.py", line 486, in send
    resp = conn.urlopen(
  File "/Users/uk/miniforge3/lib/python3.10/site-packages/urllib3/connectionpool.py", line 798, in urlopen
    retries = retries.increment(
  File "/Users/uk/miniforge3/lib/python3.10/site-packages/urllib3/util/retry.py", line 592, in increment
    raise MaxRetryError(_pool, url, error or ResponseError(cause))
urllib3.exceptions.MaxRetryError: HTTPSConnectionPool(host='www.alphavantage.co', port=443): Max retries exceeded with url: /query?function=TIME_SERIES_INTRADAY&symbol=NFLX&interval=1min&apikey=MJJTJOTUY0HJKO68 (Caused by NewConnectionError('<urllib3.connection.HTTPSConnection object at 0x144a0ffd0>: Failed to establish a new connection: [Errno 8] nodename nor servname provided, or not known'))

During handling of the above exception, another exception occurred:

Traceback (most recent call last):
  File "/Users/uk/miniforge3/lib/python3.10/site-packages/airflow/models/taskinstance.py", line 768, in _execute_task
    result = _execute_callable(context=context, **execute_callable_kwargs)
  File "/Users/uk/miniforge3/lib/python3.10/site-packages/airflow/models/taskinstance.py", line 734, in _execute_callable
    return ExecutionCallableRunner(
  File "/Users/uk/miniforge3/lib/python3.10/site-packages/airflow/utils/operator_helpers.py", line 252, in run
    return self.func(*args, **kwargs)
  File "/Users/uk/miniforge3/lib/python3.10/site-packages/airflow/models/baseoperator.py", line 424, in wrapper
    return func(self, *args, **kwargs)
  File "/Users/uk/miniforge3/lib/python3.10/site-packages/airflow/operators/python.py", line 238, in execute
    return_value = self.execute_callable()
  File "/Users/uk/miniforge3/lib/python3.10/site-packages/airflow/operators/python.py", line 256, in execute_callable
    return runner.run(*self.op_args, **self.op_kwargs)
  File "/Users/uk/miniforge3/lib/python3.10/site-packages/airflow/utils/operator_helpers.py", line 252, in run
    return self.func(*args, **kwargs)
  File "/Users/uk/airflow/dags/stock_etl_dag.py", line 20, in etl_pipeline
    data = fetch_stock_data(api_key, symbol)
  File "/Users/uk/airflow/dags/fetch_data.py", line 6, in fetch_stock_data
    response = requests.get(url)
  File "/Users/uk/miniforge3/lib/python3.10/site-packages/requests/api.py", line 73, in get
    return request("get", url, params=params, **kwargs)
  File "/Users/uk/miniforge3/lib/python3.10/site-packages/requests/api.py", line 59, in request
    return session.request(method=method, url=url, **kwargs)
  File "/Users/uk/miniforge3/lib/python3.10/site-packages/requests/sessions.py", line 589, in request
    resp = self.send(prep, **send_kwargs)
  File "/Users/uk/miniforge3/lib/python3.10/site-packages/requests/sessions.py", line 703, in send
    r = adapter.send(request, **kwargs)
  File "/Users/uk/miniforge3/lib/python3.10/site-packages/requests/adapters.py", line 519, in send
    raise ConnectionError(e, request=request)
requests.exceptions.ConnectionError: HTTPSConnectionPool(host='www.alphavantage.co', port=443): Max retries exceeded with url: /query?function=TIME_SERIES_INTRADAY&symbol=NFLX&interval=1min&apikey=MJJTJOTUY0HJKO68 (Caused by NewConnectionError('<urllib3.connection.HTTPSConnection object at 0x144a0ffd0>: Failed to establish a new connection: [Errno 8] nodename nor servname provided, or not known'))
[2025-03-27T04:43:31.674+0530] {logging_mixin.py:190} INFO - Task instance in failure state
[2025-03-27T04:43:31.674+0530] {logging_mixin.py:190} INFO - Task start:2025-03-26 23:13:31.553939+00:00 end:2025-03-26 23:13:31.674329+00:00 duration:0.12039
[2025-03-27T04:43:31.674+0530] {logging_mixin.py:190} INFO - Task:<Task(PythonOperator): run_etl> dag:<DAG: stock_etl_pipeline> dagrun:<DagRun stock_etl_pipeline @ 2025-03-26 20:40:00+00:00: scheduled__2025-03-26T20:40:00+00:00, state:running, queued_at: 2025-03-26 21:36:35.665478+00:00. externally triggered: False>
[2025-03-27T04:43:31.675+0530] {logging_mixin.py:190} INFO - Failure caused by HTTPSConnectionPool(host='www.alphavantage.co', port=443): Max retries exceeded with url: /query?function=TIME_SERIES_INTRADAY&symbol=NFLX&interval=1min&apikey=MJJTJOTUY0HJKO68 (Caused by NewConnectionError('<urllib3.connection.HTTPSConnection object at 0x144a0ffd0>: Failed to establish a new connection: [Errno 8] nodename nor servname provided, or not known'))
[2025-03-27T04:43:31.675+0530] {taskinstance.py:1226} INFO - Marking task as FAILED. dag_id=stock_etl_pipeline, task_id=run_etl, run_id=scheduled__2025-03-26T20:40:00+00:00, execution_date=20250326T204000, start_date=20250326T231331, end_date=20250326T231331
[2025-03-27T04:43:31.680+0530] {taskinstance.py:341} INFO - ::group::Post task execution logs
[2025-03-27T04:43:31.681+0530] {standard_task_runner.py:124} ERROR - Failed to execute job 126 for task run_etl (HTTPSConnectionPool(host='www.alphavantage.co', port=443): Max retries exceeded with url: /query?function=TIME_SERIES_INTRADAY&symbol=NFLX&interval=1min&apikey=MJJTJOTUY0HJKO68 (Caused by NewConnectionError('<urllib3.connection.HTTPSConnection object at 0x144a0ffd0>: Failed to establish a new connection: [Errno 8] nodename nor servname provided, or not known')); 12745)
Traceback (most recent call last):
  File "/Users/uk/miniforge3/lib/python3.10/site-packages/urllib3/connection.py", line 174, in _new_conn
    conn = connection.create_connection(
  File "/Users/uk/miniforge3/lib/python3.10/site-packages/urllib3/util/connection.py", line 72, in create_connection
    for res in socket.getaddrinfo(host, port, family, socket.SOCK_STREAM):
  File "/Users/uk/miniforge3/lib/python3.10/socket.py", line 955, in getaddrinfo
    for res in _socket.getaddrinfo(host, port, family, type, proto, flags):
socket.gaierror: [Errno 8] nodename nor servname provided, or not known

During handling of the above exception, another exception occurred:

Traceback (most recent call last):
  File "/Users/uk/miniforge3/lib/python3.10/site-packages/urllib3/connectionpool.py", line 714, in urlopen
    httplib_response = self._make_request(
  File "/Users/uk/miniforge3/lib/python3.10/site-packages/urllib3/connectionpool.py", line 403, in _make_request
    self._validate_conn(conn)
  File "/Users/uk/miniforge3/lib/python3.10/site-packages/urllib3/connectionpool.py", line 1053, in _validate_conn
    conn.connect()
  File "/Users/uk/miniforge3/lib/python3.10/site-packages/urllib3/connection.py", line 363, in connect
    self.sock = conn = self._new_conn()
  File "/Users/uk/miniforge3/lib/python3.10/site-packages/urllib3/connection.py", line 186, in _new_conn
    raise NewConnectionError(
urllib3.exceptions.NewConnectionError: <urllib3.connection.HTTPSConnection object at 0x144a0ffd0>: Failed to establish a new connection: [Errno 8] nodename nor servname provided, or not known

During handling of the above exception, another exception occurred:

Traceback (most recent call last):
  File "/Users/uk/miniforge3/lib/python3.10/site-packages/requests/adapters.py", line 486, in send
    resp = conn.urlopen(
  File "/Users/uk/miniforge3/lib/python3.10/site-packages/urllib3/connectionpool.py", line 798, in urlopen
    retries = retries.increment(
  File "/Users/uk/miniforge3/lib/python3.10/site-packages/urllib3/util/retry.py", line 592, in increment
    raise MaxRetryError(_pool, url, error or ResponseError(cause))
urllib3.exceptions.MaxRetryError: HTTPSConnectionPool(host='www.alphavantage.co', port=443): Max retries exceeded with url: /query?function=TIME_SERIES_INTRADAY&symbol=NFLX&interval=1min&apikey=MJJTJOTUY0HJKO68 (Caused by NewConnectionError('<urllib3.connection.HTTPSConnection object at 0x144a0ffd0>: Failed to establish a new connection: [Errno 8] nodename nor servname provided, or not known'))

During handling of the above exception, another exception occurred:

Traceback (most recent call last):
  File "/Users/uk/miniforge3/lib/python3.10/site-packages/airflow/task/task_runner/standard_task_runner.py", line 117, in _start_by_fork
    ret = args.func(args, dag=self.dag)
  File "/Users/uk/miniforge3/lib/python3.10/site-packages/airflow/cli/cli_config.py", line 49, in command
    return func(*args, **kwargs)
  File "/Users/uk/miniforge3/lib/python3.10/site-packages/airflow/utils/cli.py", line 116, in wrapper
    return f(*args, **kwargs)
  File "/Users/uk/miniforge3/lib/python3.10/site-packages/airflow/cli/commands/task_command.py", line 483, in task_run
    task_return_code = _run_task_by_selected_method(args, _dag, ti)
  File "/Users/uk/miniforge3/lib/python3.10/site-packages/airflow/cli/commands/task_command.py", line 256, in _run_task_by_selected_method
    return _run_raw_task(args, ti)
  File "/Users/uk/miniforge3/lib/python3.10/site-packages/airflow/cli/commands/task_command.py", line 341, in _run_raw_task
    return ti._run_raw_task(
  File "/Users/uk/miniforge3/lib/python3.10/site-packages/airflow/utils/session.py", line 97, in wrapper
    return func(*args, session=session, **kwargs)
  File "/Users/uk/miniforge3/lib/python3.10/site-packages/airflow/models/taskinstance.py", line 3006, in _run_raw_task
    return _run_raw_task(
  File "/Users/uk/miniforge3/lib/python3.10/site-packages/airflow/models/taskinstance.py", line 274, in _run_raw_task
    TaskInstance._execute_task_with_callbacks(
  File "/Users/uk/miniforge3/lib/python3.10/site-packages/airflow/models/taskinstance.py", line 3161, in _execute_task_with_callbacks
    result = self._execute_task(context, task_orig)
  File "/Users/uk/miniforge3/lib/python3.10/site-packages/airflow/models/taskinstance.py", line 3185, in _execute_task
    return _execute_task(self, context, task_orig)
  File "/Users/uk/miniforge3/lib/python3.10/site-packages/airflow/models/taskinstance.py", line 768, in _execute_task
    result = _execute_callable(context=context, **execute_callable_kwargs)
  File "/Users/uk/miniforge3/lib/python3.10/site-packages/airflow/models/taskinstance.py", line 734, in _execute_callable
    return ExecutionCallableRunner(
  File "/Users/uk/miniforge3/lib/python3.10/site-packages/airflow/utils/operator_helpers.py", line 252, in run
    return self.func(*args, **kwargs)
  File "/Users/uk/miniforge3/lib/python3.10/site-packages/airflow/models/baseoperator.py", line 424, in wrapper
    return func(self, *args, **kwargs)
  File "/Users/uk/miniforge3/lib/python3.10/site-packages/airflow/operators/python.py", line 238, in execute
    return_value = self.execute_callable()
  File "/Users/uk/miniforge3/lib/python3.10/site-packages/airflow/operators/python.py", line 256, in execute_callable
    return runner.run(*self.op_args, **self.op_kwargs)
  File "/Users/uk/miniforge3/lib/python3.10/site-packages/airflow/utils/operator_helpers.py", line 252, in run
    return self.func(*args, **kwargs)
  File "/Users/uk/airflow/dags/stock_etl_dag.py", line 20, in etl_pipeline
    data = fetch_stock_data(api_key, symbol)
  File "/Users/uk/airflow/dags/fetch_data.py", line 6, in fetch_stock_data
    response = requests.get(url)
  File "/Users/uk/miniforge3/lib/python3.10/site-packages/requests/api.py", line 73, in get
    return request("get", url, params=params, **kwargs)
  File "/Users/uk/miniforge3/lib/python3.10/site-packages/requests/api.py", line 59, in request
    return session.request(method=method, url=url, **kwargs)
  File "/Users/uk/miniforge3/lib/python3.10/site-packages/requests/sessions.py", line 589, in request
    resp = self.send(prep, **send_kwargs)
  File "/Users/uk/miniforge3/lib/python3.10/site-packages/requests/sessions.py", line 703, in send
    r = adapter.send(request, **kwargs)
  File "/Users/uk/miniforge3/lib/python3.10/site-packages/requests/adapters.py", line 519, in send
    raise ConnectionError(e, request=request)
requests.exceptions.ConnectionError: HTTPSConnectionPool(host='www.alphavantage.co', port=443): Max retries exceeded with url: /query?function=TIME_SERIES_INTRADAY&symbol=NFLX&interval=1min&apikey=MJJTJOTUY0HJKO68 (Caused by NewConnectionError('<urllib3.connection.HTTPSConnection object at 0x144a0ffd0>: Failed to establish a new connection: [Errno 8] nodename nor servname provided, or not known'))
[2025-03-27T04:43:31.711+0530] {local_task_job_runner.py:266} INFO - Task exited with return code 1
[2025-03-27T04:43:31.716+0530] {taskinstance.py:3901} INFO - 0 downstream tasks scheduled from follow-on schedule check
[2025-03-27T04:43:31.717+0530] {local_task_job_runner.py:245} INFO - ::endgroup::
